2024-04-22 08:00:11,110 ERROR: Exception on /static/img/stock_icon.png [GET] [in C:\Users\117940\OneDrive - DSM\Documents\PRIV\from_scratch\venv\Lib\site-packages\flask\app.py:828]
Traceback (most recent call last):
  File "C:\Users\117940\OneDrive - DSM\Documents\PRIV\from_scratch\venv\Lib\site-packages\sqlalchemy\engine\base.py", line 1971, in _exec_single_context
    self.dialect.do_execute(
  File "C:\Users\117940\OneDrive - DSM\Documents\PRIV\from_scratch\venv\Lib\site-packages\sqlalchemy\engine\default.py", line 919, in do_execute
    cursor.execute(statement, parameters)
sqlite3.OperationalError: database is locked

The above exception was the direct cause of the following exception:

Traceback (most recent call last):
  File "C:\Users\117940\OneDrive - DSM\Documents\PRIV\from_scratch\venv\Lib\site-packages\flask\app.py", line 1463, in wsgi_app
    response = self.full_dispatch_request()
               ^^^^^^^^^^^^^^^^^^^^^^^^^^^^
  File "C:\Users\117940\OneDrive - DSM\Documents\PRIV\from_scratch\venv\Lib\site-packages\flask\app.py", line 872, in full_dispatch_request
    rv = self.handle_user_exception(e)
         ^^^^^^^^^^^^^^^^^^^^^^^^^^^^^
  File "C:\Users\117940\OneDrive - DSM\Documents\PRIV\from_scratch\venv\Lib\site-packages\flask\app.py", line 868, in full_dispatch_request
    rv = self.preprocess_request()
         ^^^^^^^^^^^^^^^^^^^^^^^^^
  File "C:\Users\117940\OneDrive - DSM\Documents\PRIV\from_scratch\venv\Lib\site-packages\flask\app.py", line 1243, in preprocess_request
    rv = self.ensure_sync(before_func)()
         ^^^^^^^^^^^^^^^^^^^^^^^^^^^^^^^
  File "C:\Users\117940\OneDrive - DSM\Documents\PRIV\from_scratch\app\routes.py", line 20, in before_request
    db.session.commit() # committing to db
    ^^^^^^^^^^^^^^^^^^^
  File "C:\Users\117940\OneDrive - DSM\Documents\PRIV\from_scratch\venv\Lib\site-packages\sqlalchemy\orm\scoping.py", line 597, in commit
    return self._proxied.commit()
           ^^^^^^^^^^^^^^^^^^^^^^
  File "C:\Users\117940\OneDrive - DSM\Documents\PRIV\from_scratch\venv\Lib\site-packages\sqlalchemy\orm\session.py", line 1972, in commit
    trans.commit(_to_root=True)
  File "<string>", line 2, in commit
  File "C:\Users\117940\OneDrive - DSM\Documents\PRIV\from_scratch\venv\Lib\site-packages\sqlalchemy\orm\state_changes.py", line 139, in _go
    ret_value = fn(self, *arg, **kw)
                ^^^^^^^^^^^^^^^^^^^^
  File "C:\Users\117940\OneDrive - DSM\Documents\PRIV\from_scratch\venv\Lib\site-packages\sqlalchemy\orm\session.py", line 1257, in commit
    self._prepare_impl()
  File "<string>", line 2, in _prepare_impl
  File "C:\Users\117940\OneDrive - DSM\Documents\PRIV\from_scratch\venv\Lib\site-packages\sqlalchemy\orm\state_changes.py", line 139, in _go
    ret_value = fn(self, *arg, **kw)
                ^^^^^^^^^^^^^^^^^^^^
  File "C:\Users\117940\OneDrive - DSM\Documents\PRIV\from_scratch\venv\Lib\site-packages\sqlalchemy\orm\session.py", line 1232, in _prepare_impl
    self.session.flush()
  File "C:\Users\117940\OneDrive - DSM\Documents\PRIV\from_scratch\venv\Lib\site-packages\sqlalchemy\orm\session.py", line 4296, in flush
    self._flush(objects)
  File "C:\Users\117940\OneDrive - DSM\Documents\PRIV\from_scratch\venv\Lib\site-packages\sqlalchemy\orm\session.py", line 4431, in _flush
    with util.safe_reraise():
  File "C:\Users\117940\OneDrive - DSM\Documents\PRIV\from_scratch\venv\Lib\site-packages\sqlalchemy\util\langhelpers.py", line 146, in __exit__
    raise exc_value.with_traceback(exc_tb)
  File "C:\Users\117940\OneDrive - DSM\Documents\PRIV\from_scratch\venv\Lib\site-packages\sqlalchemy\orm\session.py", line 4392, in _flush
    flush_context.execute()
  File "C:\Users\117940\OneDrive - DSM\Documents\PRIV\from_scratch\venv\Lib\site-packages\sqlalchemy\orm\unitofwork.py", line 466, in execute
    rec.execute(self)
  File "C:\Users\117940\OneDrive - DSM\Documents\PRIV\from_scratch\venv\Lib\site-packages\sqlalchemy\orm\unitofwork.py", line 642, in execute
    util.preloaded.orm_persistence.save_obj(
  File "C:\Users\117940\OneDrive - DSM\Documents\PRIV\from_scratch\venv\Lib\site-packages\sqlalchemy\orm\persistence.py", line 85, in save_obj
    _emit_update_statements(
  File "C:\Users\117940\OneDrive - DSM\Documents\PRIV\from_scratch\venv\Lib\site-packages\sqlalchemy\orm\persistence.py", line 912, in _emit_update_statements
    c = connection.execute(
        ^^^^^^^^^^^^^^^^^^^
  File "C:\Users\117940\OneDrive - DSM\Documents\PRIV\from_scratch\venv\Lib\site-packages\sqlalchemy\engine\base.py", line 1422, in execute
    return meth(
           ^^^^^
  File "C:\Users\117940\OneDrive - DSM\Documents\PRIV\from_scratch\venv\Lib\site-packages\sqlalchemy\sql\elements.py", line 514, in _execute_on_connection
    return connection._execute_clauseelement(
           ^^^^^^^^^^^^^^^^^^^^^^^^^^^^^^^^^^
  File "C:\Users\117940\OneDrive - DSM\Documents\PRIV\from_scratch\venv\Lib\site-packages\sqlalchemy\engine\base.py", line 1644, in _execute_clauseelement
    ret = self._execute_context(
          ^^^^^^^^^^^^^^^^^^^^^^
  File "C:\Users\117940\OneDrive - DSM\Documents\PRIV\from_scratch\venv\Lib\site-packages\sqlalchemy\engine\base.py", line 1850, in _execute_context
    return self._exec_single_context(
           ^^^^^^^^^^^^^^^^^^^^^^^^^^
  File "C:\Users\117940\OneDrive - DSM\Documents\PRIV\from_scratch\venv\Lib\site-packages\sqlalchemy\engine\base.py", line 1990, in _exec_single_context
    self._handle_dbapi_exception(
  File "C:\Users\117940\OneDrive - DSM\Documents\PRIV\from_scratch\venv\Lib\site-packages\sqlalchemy\engine\base.py", line 2357, in _handle_dbapi_exception
    raise sqlalchemy_exception.with_traceback(exc_info[2]) from e
  File "C:\Users\117940\OneDrive - DSM\Documents\PRIV\from_scratch\venv\Lib\site-packages\sqlalchemy\engine\base.py", line 1971, in _exec_single_context
    self.dialect.do_execute(
  File "C:\Users\117940\OneDrive - DSM\Documents\PRIV\from_scratch\venv\Lib\site-packages\sqlalchemy\engine\default.py", line 919, in do_execute
    cursor.execute(statement, parameters)
sqlalchemy.exc.OperationalError: (sqlite3.OperationalError) database is locked
[SQL: UPDATE user SET last_seen=? WHERE user.id = ?]
[parameters: ('2024-04-22 06:00:05.711163', 3)]
(Background on this error at: https://sqlalche.me/e/20/e3q8)
2024-04-22 08:03:37,952 INFO: App startup [in C:\Users\117940\OneDrive - DSM\Documents\PRIV\from_scratch\app\__init__.py:197]
2024-04-22 08:19:20,623 INFO: App startup [in C:\Users\117940\OneDrive - DSM\Documents\PRIV\from_scratch\app\__init__.py:197]
2024-04-22 08:19:21,832 INFO: App startup [in C:\Users\117940\OneDrive - DSM\Documents\PRIV\from_scratch\app\__init__.py:197]
2024-04-22 08:20:38,024 INFO: App startup [in C:\Users\117940\OneDrive - DSM\Documents\PRIV\from_scratch\app\__init__.py:189]
2024-04-22 08:24:27,804 INFO: App startup [in C:\Users\117940\OneDrive - DSM\Documents\PRIV\from_scratch\app\__init__.py:189]
2024-04-22 08:24:30,356 INFO: App startup [in C:\Users\117940\OneDrive - DSM\Documents\PRIV\from_scratch\app\__init__.py:189]
2024-04-22 08:25:01,456 INFO: App startup [in C:\Users\117940\OneDrive - DSM\Documents\PRIV\from_scratch\app\__init__.py:189]
2024-04-22 08:27:58,584 INFO: App startup [in C:\Users\117940\OneDrive - DSM\Documents\PRIV\from_scratch\app\__init__.py:205]
2024-04-22 08:28:00,502 INFO: App startup [in C:\Users\117940\OneDrive - DSM\Documents\PRIV\from_scratch\app\__init__.py:205]
2024-04-22 08:31:12,102 INFO: App startup [in C:\Users\117940\OneDrive - DSM\Documents\PRIV\from_scratch\app\__init__.py:205]
2024-04-22 08:31:14,142 INFO: App startup [in C:\Users\117940\OneDrive - DSM\Documents\PRIV\from_scratch\app\__init__.py:205]
2024-04-22 08:35:45,880 INFO: App startup [in C:\Users\117940\OneDrive - DSM\Documents\PRIV\from_scratch\app\__init__.py:205]
2024-04-22 08:40:51,691 INFO: App startup [in C:\Users\117940\OneDrive - DSM\Documents\PRIV\from_scratch\app\__init__.py:205]
2024-04-22 08:48:02,807 INFO: App startup [in C:\Users\117940\OneDrive - DSM\Documents\PRIV\from_scratch\app\__init__.py:205]
2024-04-22 08:48:03,694 INFO: App startup [in C:\Users\117940\OneDrive - DSM\Documents\PRIV\from_scratch\app\__init__.py:205]
2024-04-22 08:50:20,961 INFO: App startup [in C:\Users\117940\OneDrive - DSM\Documents\PRIV\from_scratch\app\__init__.py:205]
2024-04-22 08:50:53,107 INFO: App startup [in C:\Users\117940\OneDrive - DSM\Documents\PRIV\from_scratch\app\__init__.py:205]
2024-04-22 08:51:02,424 INFO: App startup [in C:\Users\117940\OneDrive - DSM\Documents\PRIV\from_scratch\app\__init__.py:205]
2024-04-22 08:53:35,489 INFO: App startup [in C:\Users\117940\OneDrive - DSM\Documents\PRIV\from_scratch\app\__init__.py:205]
2024-04-22 08:59:33,689 INFO: App startup [in C:\Users\117940\OneDrive - DSM\Documents\PRIV\from_scratch\app\__init__.py:205]
2024-04-22 08:59:54,885 INFO: App startup [in C:\Users\117940\OneDrive - DSM\Documents\PRIV\from_scratch\app\__init__.py:205]
2024-04-22 08:59:56,002 INFO: App startup [in C:\Users\117940\OneDrive - DSM\Documents\PRIV\from_scratch\app\__init__.py:205]
2024-04-22 09:03:23,524 INFO: App startup [in C:\Users\117940\OneDrive - DSM\Documents\PRIV\from_scratch\app\__init__.py:205]
2024-04-22 09:03:24,730 INFO: App startup [in C:\Users\117940\OneDrive - DSM\Documents\PRIV\from_scratch\app\__init__.py:205]
2024-04-22 09:04:14,009 INFO: App startup [in C:\Users\117940\OneDrive - DSM\Documents\PRIV\from_scratch\app\__init__.py:205]
2024-04-22 09:04:15,986 INFO: App startup [in C:\Users\117940\OneDrive - DSM\Documents\PRIV\from_scratch\app\__init__.py:205]
2024-04-22 09:04:34,100 INFO: App startup [in C:\Users\117940\OneDrive - DSM\Documents\PRIV\from_scratch\app\__init__.py:205]
2024-04-22 09:04:35,523 INFO: App startup [in C:\Users\117940\OneDrive - DSM\Documents\PRIV\from_scratch\app\__init__.py:205]
2024-04-22 09:07:15,768 INFO: App startup [in C:\Users\117940\OneDrive - DSM\Documents\PRIV\from_scratch\app\__init__.py:205]
2024-04-22 09:07:39,247 INFO: App startup [in C:\Users\117940\OneDrive - DSM\Documents\PRIV\from_scratch\app\__init__.py:205]
